Workbook

Sheet Q1
F6: Top 3 EV 2-Wheeler Makers – FY 2023 | J6: Bottom 3 EV 2-Wheeler Makers – FY 2023
F7: Rank | G7: Maker | H7: Units Sold | J7: Rank(Bottom) | K7: Maker | L7: Unites Sold
F8: 1 | G8: ='Q1.Waste'!C10 -> OLA ELECTRIC | H8: ='Q1.Waste'!D10 -> 271925 | J8: 1 | K8: ='Q1.Waste'!F9 -> BEING | L8: ='Q1.Waste'!G9 -> 1354
F9: 2 | G9: ='Q1.Waste'!C11 -> TVS | H9: ='Q1.Waste'!D11 -> 165030 | J9: 2 | K9: ='Q1.Waste'!F10 -> JITENDRA | L9: ='Q1.Waste'!G10 -> 1180
F10: 3 | G10: ='Q1.Waste'!C9 -> ATHER | H10: ='Q1.Waste'!D9 -> 103812 | J10: 3 | K10: ='Q1.Waste'!F11 -> PURE EV | L10: ='Q1.Waste'!G11 -> 1789
F13: Top 3 EV 2-Wheeler Makers – FY 2024 | J13: Bottom 3 EV 2-Wheeler Makers – FY 2024
F14: Rank | G14: Maker | H14: Unites Sold | J14: Rank(Bottom) | K14: Maker | L14: Unites Sold
F15: 1 | G15: ='Q1.Waste'!C19 -> OLA ELECTRIC | H15: ='Q1.Waste'!D19 -> 110872 | J15: 1 | K15: ='Q1.Waste'!F19 -> HERO ELECTRIC | L15: ='Q1.Waste'!G19 -> 1052
F16: 2 | G16: ='Q1.Waste'!C20 -> TVS | H16: ='Q1.Waste'!D20 -> 55742 | J16: 2 | K16: ='Q1.Waste'!F20 -> BATTRE ELECTRIC | L16: ='Q1.Waste'!G20 -> 1128
F17: 3 | G17: ='Q1.Waste'!C21 -> BAJAJ | H17: ='Q1.Waste'!D21 -> 40072 | J17: 3 | K17: ='Q1.Waste'!F21 -> REVOLT | L17: ='Q1.Waste'!G21 -> 1582

Sheet Q1.Waste
C5: vehicle_category | D5: 2-Wheelers | F5: vehicle_category | G5: 2-Wheelers
C6: Years (date) | D6: 2023 | F6: Years (date) | G6: 2023
C8: Row Labels | D8: Sum of electric_vehicles_sold | F8: Row Labels | G8: Sum of electric_vehicles_sold
C9: ATHER | D9: 103812 | F9: BEING | G9: 1354
C10: OLA ELECTRIC | D10: 271925 | F10: JITENDRA | G10: 1180
C11: TVS | D11: 165030 | F11: PURE EV | G11: 1789
C12: Grand Total | D12: 540767 | F12: Grand Total | G12: 4323
C15: vehicle_category | D15: 2-Wheelers | F15: vehicle_category | G15: 2-Wheelers
C16: Years (date) | D16: 2024 | F16: Years (date) | G16: 2024
C18: Row Labels | D18: Sum of electric_vehicles_sold | F18: Row Labels | G18: Sum of electric_vehicles_sold
C19: OLA ELECTRIC | D19: 110872 | F19: HERO ELECTRIC | G19: 1052
C20: TVS | D20: 55742 | F20: BATTRE ELECTRIC | G20: 1128
C21: BAJAJ | D21: 40072 | F21: REVOLT | G21: 1582
C22: Grand Total | D22: 206686 | F22: Grand Total | G22: 3762

Sheet Q2
D8: Top 5 States by EV Penetration (2-Wheelers) – FY 2024 | J8: Top 5 States by EV Penetration (4-Wheelers) – FY 2024
D9: Rank | E9: State | F9: Ev Sales | G9: Total Sales | H9: Penetration Rate | J9: Rank | K9: State | L9: Ev Sales | M9: Total Sales | N9: Penetration Rate
D10: 1 | E10: ='Q2.Waste'!H5 -> Ladakh | F10: ='Q2.Waste'!I5 -> 14 | G10: ='Q2.Waste'!J5 -> 52 | H10: ='Q2.Waste'!K5 -> 0.26923077 | J10: 1 | K10: ='Q2.Waste'!H46 -> Kerala | L10: ='Q2.Waste'!I46 -> 2294 | M10: ='Q2.Waste'!J46 -> 26306 | N10: ='Q2.Waste'!K46 -> 0.08720444
D11: 2 | E11: ='Q2.Waste'!H6 -> Goa | F11: ='Q2.Waste'!I6 -> 3567 | G11: ='Q2.Waste'!J6 -> 14856 | H11: ='Q2.Waste'!K6 -> 0.24010501 | J11: 2 | K11: ='Q2.Waste'!H47 -> Chandigarh | L11: ='Q2.Waste'!I47 -> 304 | M11: ='Q2.Waste'!J47 -> 4239 | N11: ='Q2.Waste'!K47 -> 0.071715027
D12: 3 | E12: ='Q2.Waste'!H7 -> Kerala | F12: ='Q2.Waste'!I7 -> 20239 | G12: ='Q2.Waste'!J7 -> 123774 | H12: ='Q2.Waste'!K7 -> 0.16351576 | J12: 3 | K12: ='Q2.Waste'!H48 -> Goa | L12: ='Q2.Waste'!I48 -> 308 | M12: ='Q2.Waste'!J48 -> 5833 | N12: ='Q2.Waste'!K48 -> 0.052803017
D13: 4 | E13: ='Q2.Waste'!H8 -> Karnataka | F13: ='Q2.Waste'!I8 -> 47762 | G13: ='Q2.Waste'!J8 -> 348572 | H13: ='Q2.Waste'!K8 -> 0.13702191 | J13: 4 | K13: ='Q2.Waste'!H49 -> Delhi | L13: ='Q2.Waste'!I49 -> 2838 | M13: ='Q2.Waste'!J49 -> 55323 | N13: ='Q2.Waste'!K49 -> 0.051298737
D14: 5 | E14: ='Q2.Waste'!H9 -> Maharashtra | F14: ='Q2.Waste'!I9 -> 58228 | G14: ='Q2.Waste'!J9 -> 473042 | H14: ='Q2.Waste'!K9 -> 0.12309266 | J14: 5 | K14: ='Q2.Waste'!H50 -> Karnataka | L14: ='Q2.Waste'!I50 -> 3485 | M14: ='Q2.Waste'!J50 -> 82333 | N14: ='Q2.Waste'!K50 -> 0.042328107

Sheet Q2.Waste
A1: vehicle_category | B1: 2-Wheelers
A2: Years (date) | B2: 2024
A4: Row Labels | B4: Sum of electric_vehicles_sold | C4: Sum of total_vehicles_sold
A5: Maharashtra | B5: 58228 | C5: 473042 | D5: =B5/C5 -> 0.12309266 | H5: Ladakh | I5: 14 | J5: 52 | K5: 0.26923077
A6: Karnataka | B6: 47762 | C6: 348572 | D6: =B6/C6 -> 0.13702191 | H6: Goa | I6: 3567 | J6: 14856 | K6: 0.24010501
A7: Tamil Nadu | B7: 29577 | C7: 421462 | D7: =B7/C7 -> 0.070177145 | H7: Kerala | I7: 20239 | J7: 123774 | K7: 0.16351576
A8: Kerala | B8: 20239 | C8: 123774 | D8: =B8/C8 -> 0.16351576 | H8: Karnataka | I8: 47762 | J8: 348572 | K8: 0.13702191
A9: Uttar Pradesh | B9: 20024 | C9: 598729 | D9: =B9/C9 -> 0.033444179 | H9: Maharashtra | I9: 58228 | J9: 473042 | K9: 0.12309266
A10: Gujarat | B10: 19023 | C10: 275196 | D10: =B10/C10 -> 0.069125278 | H10: Chandigarh | I10: 459 | J10: 4391 | K10: 0.104532
A11: Rajasthan | B11: 17510 | C11: 249552 | D11: =B11/C11 -> 0.070165737 | H11: Delhi | I11: 10439 | J11: 100516 | K11: 0.10385411
A12: Madhya Pradesh | B12: 13462 | C12: 275164 | D12: =B12/C12 -> 0.048923551 | H12: Puducherry | I12: 1171 | J12: 14034 | K12: 0.083440217
A13: Andhra Pradesh | B13: 12021 | C13: 179338 | D13: =B13/C13 -> 0.067029854 | H13: Tamil Nadu | I13: 29577 | J13: 421462 | K13: 0.070177145
A14: Delhi | B14: 10439 | C14: 100516 | D14: =B14/C14 -> 0.10385411 | H14: Rajasthan | I14: 17510 | J14: 249552 | K14: 0.070165737
A15: Chhattisgarh | B15: 8175 | C15: 129037 | D15: =B15/C15 -> 0.063353922 | H15: Gujarat | I15: 19023 | J15: 275196 | K15: 0.069125278
A16: Odisha | B16: 7616 | C16: 110740 | D16: =B16/C16 -> 0.068773704 | H16: Odisha | I16: 7616 | J16: 110740 | K16: 0.068773704
... A39: Arunachal Pradesh | B39: 0 | C39: 3371 | D39: =B39/C39 -> 0 | H39: Arunachal Pradesh | I39: 0 | J39: 3371 | K39: 0
A40: Grand Total | B40: 292911 | C40: 4355922
A42: Years (date) | B42: 2024
A43: vehicle_category | B43: 4-Wheelers
A45: Row Labels | B45: Sum of electric_vehicles_sold | C45: Sum of total_vehicles_sold
A46: Andaman & Nicobar | B46: 0 | C46: 177 | D46: =B46/C46 -> 0 | H46: Kerala | I46: 2294 | J46: 26306 | K46: 0.08720444
A47: Andaman & Nicobar Island | B47: 2 | C47: 339 | D47: =B47/C47 -> 0.005899705 | H47: Chandigarh | I47: 304 | J47: 4239 | K47: 0.071715027
A48: Andhra Pradesh | B48: 617 | C48: 22446 | D48: =B48/C48 -> 0.027488194 | H48: Goa | I48: 308 | J48: 5833 | K48: 0.052803017
A49: Arunachal Pradesh | B49: 10 | C49: 3439 | D49: =B49/C49 -> 0.002907822 | H49: Delhi | I49: 2838 | J49: 55323 | K49: 0.051298737
A50: Assam | B50: 98 | C50: 21565 | D50: =B50/C50 -> 0.0045444006 | H50: Karnataka | I50: 3485 | J50: 82333 | K50: 0.042328107
A51: Bihar | B51: 228 | C51: 20558 | D51: =B51/C51 -> 0.011090573 | H51: West Bengal | I51: 864 | J51: 26799 | K51: 0.032240009
A52: Chandigarh | B52: 304 | C52: 4239 | D52: =B52/C52 -> 0.071715027 | H52: Maharashtra | I52: 3595 | J52: 123284 | K52: 0.029160313
A53: Chhattisgarh | B53: 310 | C53: 13419 | D53: =B53/C53 -> 0.023101572 | H53: Andhra Pradesh | I53: 617 | J53: 22446 | K53: 0.027488194
A54: Delhi | B54: 2838 | C54: 55323 | D54: =B54/C54 -> 0.051298737 | H54: Tamil Nadu | I54: 1970 | J54: 73613 | K54: 0.026761577
A55: DNH and DD | B55: 12 | C55: 1400 | D55: =B55/C55 -> 0.0085714286 | H55: Rajasthan | I55: 1508 | J55: 57838 | K55: 0.026072824
A56: Goa | B56: 308 | C56: 5833 | D56: =B56/C56 -> 0.052803017 | H56: Odisha | I56: 353 | J56: 13805 | K56: 0.025570445
A57: Gujarat | B57: 1665 | C57: 84561 | D57: =B57/C57 -> 0.019689928 | H57: Chhattisgarh | I57: 310 | J57: 13419 | K57: 0.023101572
... A77: Tripura | B77: 10 | C77: 1560 | D77: =B77/C77 -> 0.0064102564 | H77: Nagaland | I77: 1 | J77: 3035 | K77: 0.00032948929
A78: Uttar Pradesh | B78: 1182 | C78: 115929 | D78: =B78/C78 -> 0.010195896 | H78: Andaman & Nicobar | I78: 0 | J78: 177 | K78: =+E36+K78:K105 -> 0
A79: Uttarakhand | B79: 160 | C79: 16023 | D79: =B79/C79 -> 0.0099856456 | H79: Ladakh | I79: 0 | J79: 269 | K79: 0
A80: West Bengal | B80: 864 | C80: 26799 | D80: =B80/C80 -> 0.032240009 | H80: Sikkim | I80: 0 | J80: 1252 | K80: 0
A81: Grand Total | B81: 23794 | C81: 1000549

Sheet Q3
G8: States with Negative EV Penetration (2022–2024)
G9: State | H9: Penetration 2022 | I9: Penetration 2023 | J9: Change
G10: Sikkim | H10: 0 | I10: 0 | J10: 0
G11: Himachal Pradesh | H11: 0.0093451756 | I11: 0.0094391245 | J11: 9.3948887e-05
G12: Nagaland | H12: 0.00021158051 | I12: 0.00054714572 | J12: 0.00033556522
G13: Arunachal Pradesh | H13: 8.6051114e-05 | I13: 0.0014684288 | J13: 0.0013823777
G14: Tripura | H14: 0.0046883223 | I14: 0.0067114094 | J14: 0.0020230871
G15: Uttarakhand | H15: 0.02908164 | I15: 0.031667996 | J15: 0.0025863562

Sheet Q3.Waste
A1: Years (date) | B1: 2022
A3: Row Labels | B3: Sum of electric_vehicles_sold | C3: Sum of total_vehicles_sold | M3: 2022 | N3: 2024
A4: Andaman & Nicobar Island | B4: 23 | C4: 6396 | D4: =B4/C4 -> 0.0035959975 | G4: Andaman & Nicobar Island | H4: 23 | I4: 6396 | J4: 0.0035959975 | L4: Sikkim | M4: 0 | N4: 0 | O4: 0
A5: Andhra Pradesh | B5: 28050 | C5: 732826 | D5: =B5/C5 -> 0.03827648 | G5: Andhra Pradesh | H5: 28050 | I5: 732826 | J5: 0.03827648 | L5: Himachal Pradesh | M5: 0.0093451756 | N5: 0.0094391245 | O5: 9.3948887e-05
A6: Arunachal Pradesh | B6: 2 | C6: 23242 | D6: =B6/C6 -> 8.6051114e-05 | G6: Arunachal Pradesh | H6: 2 | I6: 23242 | J6: 8.6051114e-05 | L6: Nagaland | M6: 0.00021158051 | N6: 0.00054714572 | O6: 0.00033556522
A7: Assam | B7: 1984 | C7: 433527 | D7: =B7/C7 -> 0.0045764162 | G7: Assam | H7: 1984 | I7: 433527 | J7: 0.0045764162 | L7: Arunachal Pradesh | M7: 8.6051114e-05 | N7: 0.0014684288 | O7: 0.0013823777
A8: Bihar | B8: 10071 | C8: 983697 | D8: =B8/C8 -> 0.010237909 | G8: Bihar | H8: 10071 | I8: 983697 | J8: 0.010237909 | L8: Tripura | M8: 0.0046883223 | N8: 0.0067114094 | O8: 0.0020230871
A9: Chandigarh | B9: 1129 | C9: 47879 | D9: =B9/C9 -> 0.023580275 | G9: Chandigarh | H9: 1129 | I9: 47879 | J9: 0.023580275 | L9: Uttarakhand | M9: 0.02908164 | N9: 0.031667996 | O9: 0.0025863562
A10: Chhattisgarh | B10: 16760 | C10: 432818 | D10: =B10/C10 -> 0.038722974 | G10: Chhattisgarh | H10: 16760 | I10: 432818 | J10: 0.038722974 | L10: Haryana | M10: 0.020265298 | N10: 0.022968734 | O10: 0.002703436
A11: Delhi | B11: 40238 | C11: 551880 | D11: =B11/C11 -> 0.072910778 | G11: Delhi | H11: 40238 | I11: 551880 | J11: 0.072910778 | L11: Andaman & Nicobar Island | M11: 0.0035959975 | N11: 0.0071485306 | O11: 0.0035525331
A12: DNH and DD | B12: 103 | C12: 14350 | D12: =B12/C12 -> 0.0071777003 | G12: DNH and DD | H12: 103 | I12: 14350 | J12: 0.0071777003 | L12: Jharkhand | M12: 0.015290683 | N12: 0.018862767 | O12: 0.0035720837
A13: Goa | B13: 5616 | C13: 68010 | D13: =B13/C13 -> 0.082576092 | G13: Goa | H13: 5616 | I13: 68010 | J13: 0.082576092 | L13: Meghalaya | M13: 0.0010899363 | N13: 0.0050893228 | O13: 0.0039993866
A14: Gujarat | B14: 67388 | C14: 1388307 | D14: =B14/C14 -> 0.048539696 | G14: Gujarat | H14: 67388 | I14: 1388307 | J14: 0.048539696 | L14: Manipur | M14: 0.0024212145 | N14: 0.0067404079 | O14: 0.0043191934
A15: Haryana | B15: 12529 | C15: 618249 | D15: =B15/C15 -> 0.020265298 | G15: Haryana | H15: 12529 | I15: 618249 | J15: 0.020265298 | L15: Assam | M15: 0.0045764162 | N15: 0.0092405038 | O15: 0.0046640875
... A37: West Bengal | B37: 9363 | C37: 909792 | D37: =B37/C37 -> 0.010291363 | G37: West Bengal | H37: 9363 | I37: 909792 | J37: 0.010291363 | L37: Goa | M37: 0.082576092 | N37: 0.1872976 | O37: 0.10472151
A38: Grand Total | B38: 669260 | C38: 19030556 | D38: =B38/C38 -> 0.035167654
A41: Years (date) | B41: 2024
A43: Row Labels | B43: Sum of electric_vehicles_sold | C43: Sum of total_vehicles_sold
A44: Andaman & Nicobar | B44: 2 | C44: 660 | D44: =B44/C44 -> 0.003030303 | G44: Andaman & Nicobar | H44: 2 | I44: 660 | J44: 0.003030303
A45: Andaman & Nicobar Island | B45: 9 | C45: 1259 | D45: =B45/C45 -> 0.0071485306 | G45: Andaman & Nicobar Island | H45: 9 | I45: 1259 | J45: 0.0071485306
A46: Andhra Pradesh | B46: 12638 | C46: 201784 | D46: =B46/C46 -> 0.062631329 | G46: Andhra Pradesh | H46: 12638 | I46: 201784 | J46: 0.062631329
A47: Arunachal Pradesh | B47: 10 | C47: 6810 | D47: =B47/C47 -> 0.0014684288 | G47: Arunachal Pradesh | H47: 10 | I47: 6810 | J47: 0.0014684288
A48: Assam | B48: 1364 | C48: 147611 | D48: =B48/C48 -> 0.0092405038 | G48: Assam | H48: 1364 | I48: 147611 | J48: 0.0092405038
A49: Bihar | B49: 5401 | C49: 278461 | D49: =B49/C49 -> 0.019395894 | G49: Bihar | H49: 5401 | I49: 278461 | J49: 0.019395894
A50: Chandigarh | B50: 763 | C50: 8630 | D50: =B50/C50 -> 0.088412514 | G50: Chandigarh | H50: 763 | I50: 8630 | J50: 0.088412514
A51: Chhattisgarh | B51: 8485 | C51: 142456 | D51: =B51/C51 -> 0.059562251 | G51: Chhattisgarh | H51: 8485 | I51: 142456 | J51: 0.059562251
A52: Delhi | B52: 13277 | C52: 155839 | D52: =B52/C52 -> 0.085196902 | G52: Delhi | H52: 13277 | I52: 155839 | J52: 0.085196902
A53: DNH and DD | B53: 92 | C53: 4098 | D53: =B53/C53 -> 0.022449976 | G53: DNH and DD | H53: 92 | I53: 4098 | J53: 0.022449976
A54: Goa | B54: 3875 | C54: 20689 | D54: =B54/C54 -> 0.1872976 | G54: Goa | H54: 3875 | I54: 20689 | J54: 0.1872976
A55: Gujarat | B55: 20688 | C55: 359757 | D55: =B55/C55 -> 0.057505483 | G55: Gujarat | H55: 20688 | I55: 359757 | J55: 0.057505483
... A78: West Bengal | B78: 6000 | C78: 243149 | D78: =B78/C78 -> 0.024676227 | G78: West Bengal | H78: 6000 | I78: 243149 | J78: 0.024676227
A79: Grand Total | B79: 316705 | C79: 5356471 | D79: =B79/C79 -> 0.059125682

Sheet Q4
F9: Quarterly Trends for Top 5 EV Makers (4-Wheelers)
G10: Makers
F11: Quarter | G11: BYD India | H11: Hyundai Motor | I11: Mahindra & Mahindra | J11: MG Motor | K11: Tata Motors | L11: Total
F12: Q1 | G12: 487 | H12: 392 | I12: 13286 | J12: 2309 | K12: 13953 | L12: =SUM(G12:K12) -> 30427
F13: Q2 | G13: 423 | H13: 579 | I13: 9670 | J13: 3957 | K13: 18581 | L13: =SUM(G13:K13) -> 33210
F14: Q3 | G14: 454 | H14: 586 | I14: 9025 | J14: 3766 | K14: 23678 | L14: =SUM(G14:K14) -> 37509
F15: Q4 | G15: 1055 | H15: 519 | I15: 9212 | J15: 3721 | K15: 32723 | L15: =SUM(G15:K15) -> 47230

Sheet Q4.Waste
A1: vehicle_category | B1: 4-Wheelers
A2: fiscal_year | B2: All
A4: Sum of electric_vehicles_sold | B4: Column Labels
A5: Row Labels | B5: BYD India | C5: Hyundai Motor | D5: Mahindra & Mahindra | E5: MG Motor | F5: Tata Motors | G5: Grand Total
A6: Q1 | B6: 487 | C6: 392 | D6: 13286 | E6: 2309 | F6: 13953 | G6: 30427
A7: Q2 | B7: 423 | C7: 579 | D7: 9670 | E7: 3957 | F7: 18581 | G7: 33210
A8: Q3 | B8: 454 | C8: 586 | D8: 9025 | E8: 3766 | F8: 23678 | G8: 37509
A9: Q4 | B9: 1055 | C9: 519 | D9: 9212 | E9: 3721 | F9: 32723 | G9: 47230
A10: Grand Total | B10: 2419 | C10: 2076 | D10: 41193 | E10: 13753 | F10: 88935 | G10: 148376
A13: Q1 | B13: 487 | C13: 392 | D13: 13286 | E13: 2309 | F13: 13953
A14: Q2 | B14: 423 | C14: 579 | D14: 9670 | E14: 3957 | F14: 18581
A15: Q3 | B15: 454 | C15: 586 | D15: 9025 | E15: 3766 | F15: 23678
A16: Q4 | B16: 1055 | C16: 519 | D16: 9212 | E16: 3721 | F16: 32723

Sheet Q5
G8: EV Sales & Penetration Comparison (FY 2024)
G9: Delhi vs Karnataka
H10: Delhi | I10: Karnataka
G11: Ev Sales | H11: 13277 | I11: 51247
G12: Total Vehicals sold | H12: 155839 | I12: 430905
G13: Penetration Rate | H13: 0.085196902 | I13: 0.11892877

Sheet Q5.Waste
A1: Years (date) | B1: 2024
A3: Row Labels | B3: Sum of electric_vehicles_sold | C3: Sum of total_vehicles_sold
A4: Delhi | B4: 13277 | C4: 155839
A5: Karnataka | B5: 51247 | C5: 430905
A6: Grand Total | B6: 64524 | C6: 586744
B9: =A4 -> Delhi | C9: =A5 -> Karnataka
A10: Ev Sales | B10: =B4 -> 13277 | C10: =B5 -> 51247
A11: Total Vehicals sold | B11: =C4 -> 155839 | C11: =C5 -> 430905
A12: Penetration Rate | B12: =B10/B11 -> 0.085196902 | C12: =C10/C11 -> 0.11892877

Sheet Q6
I8: Top 5 Makers by CAGR (4-Wheelers)
I9: Rank | J9: Maker | K9: CAGR
I10: 1 | J10: Volvo Auto India | K10: 1.1540659
I11: 2 | J11: BMW India | K11: 0.5070456
I12: 3 | J12: Mercedes -Benz AG | K12: 0.3662601
I13: 4 | J13: BYD India | K13: 0.10263569
I14: 5 | J14: MG Motor | K14: 0.027402334

Sheet Q6.Waste
A1: vehicle_category | B1: 4-Wheelers
A3: Sum of electric_vehicles_sold | B3: Column Labels
A4: Row Labels | B4: 2022 | C4: 2024 | D4: Grand Total | I4: Makers | J4: 2022 | K4: 2024 | L4: CAGR
A5: BMW India | B5: 118 | C5: 268 | D5: 386 | F5: =(C5/B5)^(1/2)-1 -> 0.5070456 | I5: PCA Automobiles | J5: 0 | K5: 217 | L5: #DIV/0!
A6: BYD India | B6: 329 | C6: 400 | D6: 729 | F6: =(C6/B6)^(1/2)-1 -> 0.10263569 | I6: Volvo Auto India | J6: 25 | K6: 116 | L6: 1.1540659
A7: Hyundai Motor | B7: 447 | C7: 338 | D7: 785 | F7: =(C7/B7)^(1/2)-1 -> -0.13042992 | I7: BMW India | J7: 118 | K7: 268 | L7: 0.5070456
A8: KIA Motors | B8: 155 | C8: 72 | D8: 227 | F8: =(C8/B8)^(1/2)-1 -> -0.3184458 | I8: Mercedes -Benz AG | J8: 45 | K8: 84 | L8: 0.3662601
A9: Mahindra & Mahindra | B9: 10215 | C9: 2316 | D9: 12531 | F9: =(C9/B9)^(1/2)-1 -> -0.52384309 | I9: BYD India | J9: 329 | K9: 400 | L9: 0.10263569
A10: Mercedes -Benz AG | B10: 45 | C10: 84 | D10: 129 | F10: =(C10/B10)^(1/2)-1 -> 0.3662601 | I10: MG Motor | J10: 2484 | K10: 2622 | L10: 0.027402334
A11: MG Motor | B11: 2484 | C11: 2622 | D11: 5106 | F11: =(C11/B11)^(1/2)-1 -> 0.027402334 | I11: Hyundai Motor | J11: 447 | K11: 338 | L11: -0.13042992
A12: PCA Automobiles | B12: 0 | C12: 217 | D12: 217 | F12: =(C12/B12)^(1/2)-1 -> #DIV/0! | I12: Tata Motors | J12: 24352 | K12: 17361 | L12: -0.15565478
A13: Tata Motors | B13: 24352 | C13: 17361 | D13: 41713 | F13: =(C13/B13)^(1/2)-1 -> -0.15565478 | I13: KIA Motors | J13: 155 | K13: 72 | L13: -0.3184458
A14: Volvo Auto India | B14: 25 | C14: 116 | D14: 141 | F14: =(C14/B14)^(1/2)-1 -> 1.1540659 | I14: Mahindra & Mahindra | J14: 10215 | K14: 2316 | L14: -0.52384309
A15: Grand Total | B15: 38170 | C15: 23794 | D15: 61964

Sheet Q7
G6: Top 10 States by CAGR (Total Vehicle Sales) – 2022–2024
G7: Rank | H7: state | I7: CAGR
G8: 1 | H8: Nagaland | I8: -0.37814902
G9: 2 | H9: Puducherry | I9: -0.40633131
G10: 3 | H10: Assam | I10: -0.41648599
G11: 4 | H11: Chhattisgarh | I11: -0.42629621
G12: 5 | H12: Haryana | I12: -0.42961151
G13: 6 | H13: Karnataka | I13: -0.43361085
G14: 7 | H14: Meghalaya | I14: -0.43608763
G15: 8 | H15: Tamil Nadu | I15: -0.43790158
G16: 9 | H16: Mizoram | I16: -0.44676612
G17: 10 | H17: Goa | I17: -0.44845194

Sheet Q7.Waste
A3: Sum of total_vehicles_sold | B3: Column Labels
A4: Row Labels | B4: 2022 | C4: 2024 | D4: Grand Total
A5: Andaman & Nicobar | C5: 660 | D5: 660 | F5: states | G5: 2022 | H5: 2024 | I5: CAGR
A6: Andaman & Nicobar Island | B6: 6396 | C6: 1259 | D6: 7655 | F6: Nagaland | G6: 14179 | H6: 5483 | I6: -0.37814902
A7: Andhra Pradesh | B7: 732826 | C7: 201784 | D7: 934610 | F7: Puducherry | G7: 49662 | H7: 17503 | I7: -0.40633131
A8: Arunachal Pradesh | B8: 23242 | C8: 6810 | D8: 30052 | F8: Assam | G8: 433527 | H8: 147611 | I8: -0.41648599
A9: Assam | B9: 433527 | C9: 147611 | D9: 581138 | F9: Chhattisgarh | G9: 432818 | H9: 142456 | I9: -0.42629621
A10: Bihar | B10: 983697 | C10: 278461 | D10: 1262158 | F10: Haryana | G10: 618249 | H10: 201143 | I10: -0.42961151
A11: Chandigarh | B11: 47879 | C11: 8630 | D11: 56509 | F11: Karnataka | G11: 1343234 | H11: 430905 | I11: -0.43361085
A12: Chhattisgarh | B12: 432818 | C12: 142456 | D12: 575274 | F12: Meghalaya | G12: 30277 | H12: 9628 | I12: -0.43608763
A13: Delhi | B13: 551880 | C13: 155839 | D13: 707719 | F13: Tamil Nadu | G13: 1566918 | H13: 495075 | I13: -0.43790158
A14: DNH and DD | B14: 14350 | C14: 4098 | D14: 18448 | F14: Mizoram | G14: 24243 | H14: 7420 | I14: -0.44676612
A15: Goa | B15: 68010 | C15: 20689 | D15: 88699 | F15: Goa | G15: 68010 | H15: 20689 | I15: -0.44845194
A16: Gujarat | B16: 1388307 | C16: 359757 | D16: 1748064 | F16: Punjab | G16: 500353 | H16: 147146 | I16: -0.45770453
A17: Haryana | B17: 618249 | C17: 201143 | D17: 819392 | F17: Arunachal Pradesh | G17: 23242 | H17: 6810 | I17: -0.45870152
... A39: West Bengal | B39: 909792 | C39: 243149 | D39: 1152941 | F39: Ladakh | G39: 4451 | H39: 321 | I39: -0.73145089
A40: Grand Total | B40: 19030556 | C40: 5356471 | D40: 24387027

Sheet Q8
H7: Monthly EV Sales Summary
H8: ='Q8.Waste'!A4 -> Jan | I8: ='Q8.Waste'!B4 -> 189099
H9: ='Q8.Waste'!A5 -> Feb | I9: ='Q8.Waste'!B5 -> 198049
H10: ='Q8.Waste'!A6 -> Mar | I10: ='Q8.Waste'!B6 -> 291587
H11: ='Q8.Waste'!A7 -> Apr | I11: ='Q8.Waste'!B7 -> 134657
H12: ='Q8.Waste'!A8 -> May | I12: ='Q8.Waste'!B8 -> 159869
H13: ='Q8.Waste'!A9 -> Jun | I13: ='Q8.Waste'!B9 -> 106709
H14: ='Q8.Waste'!A10 -> Jul | I14: ='Q8.Waste'!B10 -> 127426
H15: ='Q8.Waste'!A11 -> Aug | I15: ='Q8.Waste'!B11 -> 141961
H16: ='Q8.Waste'!A12 -> Sep | I16: ='Q8.Waste'!B12 -> 145972
H17: ='Q8.Waste'!A13 -> Oct | I17: ='Q8.Waste'!B13 -> 185185
H18: ='Q8.Waste'!A14 -> Nov | I18: ='Q8.Waste'!B14 -> 205196
H19: ='Q8.Waste'!A15 -> Dec | I19: ='Q8.Waste'!B15 -> 180401

Sheet Q8.Waste
A3: Row Labels | B3: Sum of electric_vehicles_sold
A4: Jan | B4: 189099
A5: Feb | B5: 198049
A6: Mar | B6: 291587
A7: Apr | B7: 134657
A8: May | B8: 159869
A9: Jun | B9: 106709
A10: Jul | B10: 127426
A11: Aug | B11: 141961
A12: Sep | B12: 145972
A13: Oct | B13: 185185
A14: Nov | B14: 205196
A15: Dec | B15: 180401
A16: Grand Total | B16: 2066111

Sheet Q9
G3: EV Sales Projection for 2030 (Based on CAGR 2022–2024)
G4: Rank | H4: State | I4: 2024 Sales | J4: CAGR | K4: Projected 2030 Sales
G5: 1 | H5: Uttar Pradesh | I5: 21206 | J5: -0.05588906 | K5: 15017.476
G6: 2 | H6: Karnataka | I6: 51247 | J6: -0.25058061 | K6: 9078.5816
G7: 3 | H7: Mizoram | I7: 138 | J7: 0.95789002 | K7: 7773.3611
G8: 4 | H8: Maharashtra | I8: 61823 | J8: -0.30838972 | K8: 6765.7933
G9: 5 | H9: Kerala | I9: 22533 | J9: -0.22232213 | K9: 4984.4524
G10: 6 | H10: Tamil Nadu | I10: 31547 | J10: -0.29836539 | K10: 3763.7788
G11: 7 | H11: Madhya Pradesh | I11: 13923 | J11: -0.22114584 | K11: 3107.919
G12: 8 | H12: West Bengal | I12: 6000 | J12: -0.19948751 | K12: 1578.9193
G13: 9 | H13: Goa | I13: 3875 | J13: -0.1693419 | K13: 1272.933
G14: 10 | H14: Arunachal Pradesh | I14: 10 | J14: 1.236068 | K14: 1250
G15: 11 | H15: Andhra Pradesh | I15: 12638 | J15: -0.32876786 | K15: 1155.8855
G16: 12 | H16: Chhattisgarh | I16: 8485 | J16: -0.28847704 | K16: 1100.995
... G37: 33 | H37: Andaman & Nicobar Island | I37: 9 | J37: -0.37445676 | K37: 0.5392455

Sheet Q9.Waste
A3: Sum of electric_vehicles_sold | B3: Column Labels
A4: Row Labels | B4: 2022 | C4: 2024 | D4: Grand Total | F4: State | G4: 2022 | H4: 2024 | I4: CAGR | J4: 2030
A5: Andaman & Nicobar | C5: 2 | D5: 2 | F5: Andaman & Nicobar | G5: 0 | H5: 2 | I5: #DIV/0! | J5: #DIV/0!
A6: Andaman & Nicobar Island | B6: 23 | C6: 9 | D6: 32 | F6: Andaman & Nicobar Island | G6: 23 | H6: 9 | I6: -0.37445676 | J6: 0.5392455
A7: Andhra Pradesh | B7: 28050 | C7: 12638 | D7: 40688 | F7: Andhra Pradesh | G7: 28050 | H7: 12638 | I7: -0.32876786 | J7: 1155.8855
A8: Arunachal Pradesh | B8: 2 | C8: 10 | D8: 12 | F8: Arunachal Pradesh | G8: 2 | H8: 10 | I8: 1.236068 | J8: 1250
A9: Assam | B9: 1984 | C9: 1364 | D9: 3348 | F9: Assam | G9: 1984 | H9: 1364 | I9: -0.1708438 | J9: 443.2334
A10: Bihar | B10: 10071 | C10: 5401 | D10: 15472 | F10: Bihar | G10: 10071 | H10: 5401 | I10: -0.26768018 | J10: 833.06506
A11: Chandigarh | B11: 1129 | C11: 763 | D11: 1892 | F11: Chandigarh | G11: 1129 | H11: 763 | I11: -0.1779177 | J11: 235.51378
A12: Chhattisgarh | B12: 16760 | C12: 8485 | D12: 25245 | F12: Chhattisgarh | G12: 16760 | H12: 8485 | I12: -0.28847704 | J12: 1100.995
A13: Delhi | B13: 40238 | C13: 13277 | D13: 53515 | F13: Delhi | G13: 40238 | H13: 13277 | I13: -0.42557705 | J13: 476.96956
A14: DNH and DD | B14: 103 | C14: 92 | D14: 195 | F14: DNH and DD | G14: 103 | H14: 92 | I14: -0.054905357 | J14: 65.560104
A15: Goa | B15: 5616 | C15: 3875 | D15: 9491 | F15: Goa | G15: 5616 | H15: 3875 | I15: -0.1693419 | J15: 1272.933
A16: Gujarat | B16: 67388 | C16: 20688 | D16: 88076 | F16: Gujarat | G16: 67388 | H16: 20688 | I16: -0.44592575 | J16: 598.58569
A17: Haryana | B17: 12529 | C17: 4620 | D17: 17149 | F17: Haryana | G17: 12529 | H17: 4620 | I17: -0.39275663 | J17: 231.64273
... A33: Rajasthan | B33: 55600 | C33: 19018 | D33: 74618 | F33: Rajasthan | G33: 55600 | H33: 19018 | I33: -0.41514928 | J33: 761.08822
A34: Sikkim | B34: 0 | C34: 0 | D34: 0 | F34: Sikkim | G34: 0 | H34: 0 | I34: #DIV/0! | J34: #DIV/0!
A35: Tamil Nadu | B35: 64082 | C35: 31547 | D35: 95629 | F35: Tamil Nadu | G35: 64082 | H35: 31547 | I35: -0.29836539 | J35: 3763.7788
A36: Tripura | B36: 196 | C36: 78 | D36: 274 | F36: Tripura | G36: 196 | H36: 78 | I36: -0.36915994 | J36: 4.915981
A37: Uttar Pradesh | B37: 23791 | C37: 21206 | D37: 44997 | F37: Uttar Pradesh | G37: 23791 | H37: 21206 | I37: -0.05588906 | J37: 15017.476
A38: Uttarakhand | B38: 6081 | C38: 1707 | D38: 7788 | F38: Uttarakhand | G38: 6081 | H38: 1707 | I38: -0.47017889 | J38: 37.758008
A39: West Bengal | B39: 9363 | C39: 6000 | D39: 15363 | F39: West Bengal | G39: 9363 | H39: 6000 | I39: -0.19948751 | J39: 1578.9193
A40: Grand Total | B40: 669260 | C40: 316705 | D40: 985965
B44: State | C44: 2022 | D44: 2024 | E44: CAGR | F44: 2030
B45: Uttar Pradesh | C45: 23791 | D45: 21206 | E45: -0.05588906 | F45: 15017.476
B46: Karnataka | C46: 91247 | D46: 51247 | E46: -0.25058061 | F46: 9078.5816
B47: Mizoram | C47: 36 | D47: 138 | E47: 0.95789002 | F47: 7773.3611
B48: Maharashtra | C48: 129249 | D48: 61823 | E48: -0.30838972 | F48: 6765.7933
B49: Kerala | C49: 37258 | D49: 22533 | E49: -0.22232213 | F49: 4984.4524
B50: Tamil Nadu | C50: 64082 | D50: 31547 | E50: -0.29836539 | F50: 3763.7788
B51: Madhya Pradesh | C51: 22952 | D51: 13923 | E51: -0.22114584 | F51: 3107.919
B52: West Bengal | C52: 9363 | D52: 6000 | E52: -0.19948751 | F52: 1578.9193
B53: Goa | C53: 5616 | D53: 3875 | E53: -0.1693419 | F53: 1272.933
B54: Arunachal Pradesh | C54: 2 | D54: 10 | E54: 1.236068 | F54: 1250
B55: Andhra Pradesh | C55: 28050 | D55: 12638 | E55: -0.32876786 | F55: 1155.8855
B56: Chhattisgarh | C56: 16760 | D56: 8485 | E56: -0.28847704 | F56: 1100.995
... B77: Andaman & Nicobar Island | C77: 23 | D77: 9 | E77: -0.37445676 | F77: 0.5392455

Sheet Q10
H7: Revenue Growth Rate of EVs in India
H8: Category | I8: Growth(2022-2024) | J8: Growth(2023-2024)
H9: 2-Wheelers | I9: -0.53586493 | J9: -0.65814812
H10: 4-Wheelers | I10: -0.37663086 | J10: -0.70302418

Sheet Q10.Waste
A1: vehicle_category | B1: 2-Wheelers | D1: vehicle_category | E1: 4-Wheelers
A3: Row Labels | B3: Sum of electric_vehicles_sold | C3: 2W Revenue | D3: Row Labels | E3: Sum of electric_vehicles_sold
A4: 2022 | B4: 631090 | C4: =B4*85000 -> 53642650000 | D4: 2022 | E4: 38170 | F4: =E4*1500000 -> 57255000000
A5: 2023 | B5: 856836 | C5: =B5*85000 -> 72831060000 | D5: 2023 | E5: 80121 | F5: =E5*1500000 -> 120181500000
A6: 2024 | B6: 292911 | C6: =B6*85000 -> 24897435000 | D6: 2024 | E6: 23794 | F6: =E6*1500000 -> 35691000000
A7: Grand Total | B7: 1780837 | D7: Grand Total | E7: 142085
B9: Year | C9: 2w Sales | D9: 2W Revenue | E9: 4W Sales | F9: 4W Revenue
B10: =A4 -> 2022 | C10: =B4 -> 631090 | D10: =C4 -> 53642650000 | E10: =E4 -> 38170 | F10: =F4 -> 57255000000
B11: =A5 -> 2023 | C11: =B5 -> 856836 | D11: =C5 -> 72831060000 | E11: =E5 -> 80121 | F11: =F5 -> 120181500000
B12: =A6 -> 2024 | C12: =B6 -> 292911 | D12: =C6 -> 24897435000 | E12: =E6 -> 23794 | F12: =F6 -> 35691000000
A15: Category | B15: Growth(2022-2024) | C15: Growth(2023-2024)
A16: 2-Wheelers | B16: -0.53586493 | C16: -0.65814812
A17: 4-Wheelers | B17: -0.37663086 | C17: -0.70302418

Sheet DashBoard

Sheet KPIs
A3: Sum of electric_vehicles_sold | D3: Column Labels | I3: KPIs
A4: 2066111 | D4: 2023 | E4: 2024 | F4: Grand Total | I4: Total EV sold | J4: Growth | K4: EV Penetration | L4: Top State (EV) | M4: CAGR
C5: Sum of electric_vehicles_sold | D5: 936957 | E5: 316705 | F5: 1253662 | I5: =A4 -> 2066111 | J5: =D7 -> -66.198556 | K5: =B12 -> 3.6108037 | L5: =A19 -> Maharashtra | M5: =B26 -> -0.31209253
C7: Growth(%) | D7: =(E5-D5)/D5*100 -> -66.198556
A9: Sum of electric_vehicles_sold | B9: Sum of total_vehicles_sold
A10: 2066111 | B10: 57220252
B12: =(A10/B10)*100 -> 3.6108037
A14: Sum of electric_vehicles_sold
A15: 2066111
A18: Row Labels | B18: Sum of electric_vehicles_sold
A19: Maharashtra | B19: 396045
A20: Grand Total | B20: 396045
B22: Column Labels
B23: 2022 | C23: 2024 | D23: Grand Total
A24: Sum of electric_vehicles_sold | B24: 669260 | C24: 316705 | D24: 985965
B26: =(C24/B24)^(1/2)-1 -> -0.31209253
A30: Row Labels | B30: Sum of electric_vehicles_sold | C30: Sum of total_vehicles_sold | D30: rate | I30: State | J30: Ev Sold | K30: Total Vehical Sold | L30: Penetration Rate | N30: State | O30: Ev Sold | P30: Total Vehical Sold | Q30: Penetration Rate | T30: =N30 -> State | U30: =Q30 -> Penetration Rate
A31: Andaman & Nicobar | B31: 2 | C31: 660 | D31: =B31/C31 -> 0.003030303 | F31: =B31/C31 -> 0.003030303 | I31: =A31 -> Andaman & Nicobar | J31: =B31 -> 2 | K31: =C31 -> 660 | L31: =D31 -> 0.003030303 | N31: Goa | O31: 19684 | P31: 199970 | Q31: 0.098434765 | T31: =N31 -> Goa | U31: =Q31 -> 0.098434765
A32: Andaman & Nicobar Island | B32: 78 | C32: 18225 | D32: =B32/C32 -> 0.0042798354 | F32: =B32/C32 -> 0.0042798354 | I32: =A32 -> Andaman & Nicobar Island | J32: =B32 -> 78 | K32: =C32 -> 18225 | L32: =D32 -> 0.0042798354 | N32: Karnataka | O32: 312995 | P32: 3994329 | Q32: 0.078359845 | T32: =N32 -> Karnataka | U32: =Q32 -> 0.078359845
A33: Andhra Pradesh | B33: 77422 | C33: 2283871 | D33: =B33/C33 -> 0.033899463 | F33: =B33/C33 -> 0.033899463 | I33: =A33 -> Andhra Pradesh | J33: =B33 -> 77422 | K33: =C33 -> 2283871 | L33: =D33 -> 0.033899463 | N33: Delhi | O33: 107312 | P33: 1588436 | Q33: 0.067558277 | T33: =N33 -> Delhi | U33: =Q33 -> 0.067558277
A34: Arunachal Pradesh | B34: 33 | C34: 71547 | D34: =B34/C34 -> 0.00046123527 | F34: =B34/C34 -> 0.00046123527 | I34: =A34 -> Arunachal Pradesh | J34: =B34 -> 33 | K34: =C34 -> 71547 | L34: =D34 -> 0.00046123527 | N34: Kerala | O34: 137060 | P34: 2064677 | Q34: 0.066383265 | T34: =N34 -> Kerala | U34: =Q34 -> 0.066383265
A35: Assam | B35: 6418 | C35: 1403271 | D35: =B35/C35 -> 0.0045735998 | F35: =B35/C35 -> 0.0045735998 | I35: =A35 -> Assam | J35: =B35 -> 6418 | K35: =C35 -> 1403271 | L35: =D35 -> 0.0045735998 | N35: Maharashtra | O35: 396045 | P35: 6101429 | Q35: 0.064910204 | T35: =N35 -> Maharashtra | U35: =Q35 -> 0.064910204
A36: Bihar | B36: 31019 | C36: 3048373 | D36: =B36/C36 -> 0.010175592 | F36: =B36/C36 -> 0.010175592 | I36: =A36 -> Bihar | J36: =B36 -> 31019 | K36: =C36 -> 3048373 | L36: =D36 -> 0.010175592 | N36: Odisha | O36: 78267 | P36: 1688794 | Q36: 0.046344906
A37: Chandigarh | B37: 5279 | C37: 130628 | D37: =B37/C37 -> 0.040412469 | F37: =B37/C37 -> 0.040412469 | I37: =A37 -> Chandigarh | J37: =B37 -> 5279 | K37: =C37 -> 130628 | L37: =D37 -> 0.040412469 | N37: Rajasthan | O37: 150366 | P37: 3307591 | Q37: 0.045460881
A38: Chhattisgarh | B38: 53804 | C38: 1334989 | D38: =B38/C38 -> 0.040302954 | F38: =B38/C38 -> 0.040302954 | I38: =A38 -> Chhattisgarh | J38: =B38 -> 53804 | K38: =C38 -> 1334989 | L38: =D38 -> 0.040302954 | N38: Gujarat | O38: 181389 | P38: 4125551 | Q38: 0.043967218
A39: Delhi | B39: 107312 | C39: 1588436 | D39: =B39/C39 -> 0.067558277 | F39: =B39/C39 -> 0.067558277 | I39: =A39 -> Delhi | J39: =B39 -> 107312 | K39: =C39 -> 1588436 | L39: =D39 -> 0.067558277 | N39: Tamil Nadu | O39: 200062 | P39: 4652363 | Q39: 0.043002233
A40: DNH and DD | B40: 355 | C40: 43397 | D40: =B40/C40 -> 0.008180289 | F40: =B40/C40 -> 0.008180289 | I40: =A40 -> DNH and DD | J40: =B40 -> 355 | K40: =C40 -> 43397 | L40: =D40 -> 0.008180289 | N40: Chandigarh | O40: 5279 | P40: 130628 | Q40: 0.040412469
A41: Goa | B41: 19684 | C41: 199970 | D41: =B41/C41 -> 0.098434765 | F41: =B41/C41 -> 0.098434765 | I41: =A41 -> Goa | J41: =B41 -> 19684 | K41: =C41 -> 199970 | L41: =D41 -> 0.098434765 | N41: Chhattisgarh | O41: 53804 | P41: 1334989 | Q41: 0.040302954
A42: Gujarat | B42: 181389 | C42: 4125551 | D42: =B42/C42 -> 0.043967218 | F42: =B42/C42 -> 0.043967218 | I42: =A42 -> Gujarat | J42: =B42 -> 181389 | K42: =C42 -> 4125551 | L42: =D42 -> 0.043967218 | N42: Puducherry | O42: 5536 | P42: 150798 | Q42: 0.036711362
A43: Haryana | B43: 30797 | C43: 1902768 | D43: =B43/C43 -> 0.016185368 | F43: =B43/C43 -> 0.016185368 | I43: =A43 -> Haryana | J43: =B43 -> 30797 | K43: =C43 -> 1902768 | L43: =D43 -> 0.016185368 | N43: Andhra Pradesh | O43: 77422 | P43: 2283871 | Q43: 0.033899463
A44: Himachal Pradesh | B44: 2595 | C44: 325366 | D44: =B44/C44 -> 0.0079756336 | F44: =B44/C44 -> 0.0079756336 | I44: =A44 -> Himachal Pradesh | J44: =B44 -> 2595 | K44: =C44 -> 325366 | L44: =D44 -> 0.0079756336 | N44: Uttarakhand | O44: 15127 | P44: 622707 | Q44: 0.024292324
A45: Jammu and Kashmir | B45: 5971 | C45: 414553 | D45: =B45/C45 -> 0.014403466 | F45: =B45/C45 -> 0.014403466 | I45: =A45 -> Jammu and Kashmir | J45: =B45 -> 5971 | K45: =C45 -> 414553 | L45: =D45 -> 0.014403466 | N45: Madhya Pradesh | O45: 78979 | P45: 3498698 | Q45: 0.022573826
A46: Jharkhand | B46: 18461 | C46: 1364886 | D46: =B46/C46 -> 0.013525672 | F46: =B46/C46 -> 0.013525672 | I46: =A46 -> Jharkhand | J46: =B46 -> 18461 | K46: =C46 -> 1364886 | L46: =D46 -> 0.013525672 | N46: Haryana | O46: 30797 | P46: 1902768 | Q46: 0.016185368
A47: Karnataka | B47: 312995 | C47: 3994329 | D47: =B47/C47 -> 0.078359845 | F47: =B47/C47 -> 0.078359845 | I47: =A47 -> Karnataka | J47: =B47 -> 312995 | K47: =C47 -> 3994329 | L47: =D47 -> 0.078359845 | N47: Punjab | O47: 23833 | P47: 1543962 | Q47: 0.015436261
... A65: West Bengal | B65: 30560 | C65: 2736176 | D65: =B65/C65 -> 0.011168872 | F65: =B65/C65 -> 0.011168872 | I65: =A65 -> West Bengal | J65: =B65 -> 30560 | K65: =C65 -> 2736176 | L65: =D65 -> 0.011168872 | N65: Sikkim | O65: 0 | P65: 29346 | Q65: 0
A66: Grand Total | B66: 2066111 | C66: 57220252 | D66: =B66/C66 -> 0.036108037
A70: Row Labels | B70: Sum of electric_vehicles_sold
A71: Jan | B71: 189099
A72: Feb | B72: 198049
A73: Mar | B73: 291587
...

Sheet electric_vehicle_sales_by_state
A1: date | B1: state | C1: vehicle_category | D1: electric_vehicles_sold | E1: total_vehicles_sold
A2: 44287 | B2: Sikkim | C2: 2-Wheelers | D2: 0 | E2: 398
A3: 44287 | B3: Sikkim | C3: 4-Wheelers | D3: 0 | E3: 361
A4: 44317 | B4: Sikkim | C4: 2-Wheelers | D4: 0 | E4: 113
A5: 44317 | B5: Sikkim | C5: 4-Wheelers | D5: 0 | E5: 98
A6: 44348 | B6: Sikkim | C6: 2-Wheelers | D6: 0 | E6: 229
A7: 44348 | B7: Sikkim | C7: 4-Wheelers | D7: 0 | E7: 244
A8: 44378 | B8: Sikkim | C8: 2-Wheelers | D8: 0 | E8: 458
A9: 44378 | B9: Sikkim | C9: 4-Wheelers | D9: 0 | E9: 452
A10: 44409 | B10: Sikkim | C10: 2-Wheelers | D10: 0 | E10: 489
A11: 44409 | B11: Sikkim | C11: 4-Wheelers | D11: 0 | E11: 408
A12: 44440 | B12: Sikkim | C12: 2-Wheelers | D12: 0 | E12: 540
A13: 44440 | B13: Sikkim | C13: 4-Wheelers | D13: 0 | E13: 355
... A2446: 45352 | B2446: Nagaland | C2446: 2-Wheelers | D2446: 2 | E2446: 1180

Sheet electric_vehicle_sales_by_maker
A1: date | B1: vehicle_category | C1: maker | D1: electric_vehicles_sold
A2: 44287 | B2: 2-Wheelers | C2: OLA ELECTRIC | D2: 0
A3: 44652 | B3: 2-Wheelers | C3: OKAYA EV | D3: 0
A4: 44317 | B4: 2-Wheelers | C4: OLA ELECTRIC | D4: 0
A5: 44348 | B5: 2-Wheelers | C5: OLA ELECTRIC | D5: 0
A6: 44378 | B6: 2-Wheelers | C6: OLA ELECTRIC | D6: 0
A7: 44409 | B7: 2-Wheelers | C7: OLA ELECTRIC | D7: 0
A8: 44440 | B8: 2-Wheelers | C8: OLA ELECTRIC | D8: 0
A9: 44470 | B9: 2-Wheelers | C9: OLA ELECTRIC | D9: 0
A10: 44501 | B10: 2-Wheelers | C10: OLA ELECTRIC | D10: 0
A11: 44287 | B11: 4-Wheelers | C11: BYD India | D11: 0
A12: 44287 | B12: 4-Wheelers | C12: PCA Automobiles | D12: 0
A13: 44287 | B13: 4-Wheelers | C13: BMW India | D13: 0
... A817: 45352 | B817: 2-Wheelers | C817: OTHERS | D817: 10579

Sheet dim_date
A1: date | B1: fiscal_year | C1: quarter | D1: Month_Name
A2: 44287 | B2: 2022 | C2: Q1 | D2: =TEXT(dim_date[[#This Row],[date]],"mmm") -> Apr
A3: 44317 | B3: 2022 | C3: Q1 | D3: =TEXT(dim_date[[#This Row],[date]],"mmm") -> May
A4: 44348 | B4: 2022 | C4: Q1 | D4: =TEXT(dim_date[[#This Row],[date]],"mmm") -> Jun
A5: 44378 | B5: 2022 | C5: Q2 | D5: =TEXT(dim_date[[#This Row],[date]],"mmm") -> Jul
A6: 44409 | B6: 2022 | C6: Q2 | D6: =TEXT(dim_date[[#This Row],[date]],"mmm") -> Aug
A7: 44440 | B7: 2022 | C7: Q2 | D7: =TEXT(dim_date[[#This Row],[date]],"mmm") -> Sep
A8: 44470 | B8: 2022 | C8: Q3 | D8: =TEXT(dim_date[[#This Row],[date]],"mmm") -> Oct
A9: 44501 | B9: 2022 | C9: Q3 | D9: =TEXT(dim_date[[#This Row],[date]],"mmm") -> Nov
A10: 44531 | B10: 2022 | C10: Q3 | D10: =TEXT(dim_date[[#This Row],[date]],"mmm") -> Dec
A11: 44562 | B11: 2022 | C11: Q4 | D11: =TEXT(dim_date[[#This Row],[date]],"mmm") -> Jan
A12: 44593 | B12: 2022 | C12: Q4 | D12: =TEXT(dim_date[[#This Row],[date]],"mmm") -> Feb
A13: 44621 | B13: 2022 | C13: Q4 | D13: =TEXT(dim_date[[#This Row],[date]],"mmm") -> Mar
... A37: 45352 | B37: 2024 | C37: Q4 | D37: =TEXT(dim_date[[#This Row],[date]],"mmm") -> Mar

Sheet datasets
A1: Name | B1: Extension | C1: Date accessed | D1: Date modified | E1: Date created | F1: Folder Path
A2: dim_date.csv | B2: .csv | C2: 46109.47 | D2: 46074.781 | E2: 45492.558 | F2: C:\Users\Win11\Desktop\Code Basics\RPC12_Input_For_Participants\datasets\
A3: electric_vehicle_sales_by_makers.csv | B3: .csv | C3: 46109.458 | D3: 46074.781 | E3: 45492.558 | F3: C:\Users\Win11\Desktop\Code Basics\RPC12_Input_For_Participants\datasets\
A4: electric_vehicle_sales_by_state.csv | B4: .csv | C4: 46109.471 | D4: 46074.781 | E4: 45492.558 | F4: C:\Users\Win11\Desktop\Code Basics\RPC12_Input_For_Participants\datasets\
